Workbook

Sheet Output Data
A1: UN Global Hackathon — Structured Output Template
A2: Final Round submission | due 30 September 2026 | All RDTII 2.1 pillars; pillars 6 and 7 are mandatory. Same columns as Round 1, plus Language of Source. Indicator IDs are written 6.1, 7.3, 12.9 — as text, never as numbers.
A3: REQUIRED | B3: REQUIRED | C3: OPTIONAL | D3: REQUIRED | E3: REQUIRED | F3: REQUIRED | G3: REQUIRED | H3: OPTIONAL | I3: REQUIRED | J3: OPTIONAL | K3: REQUIRED | L3: OPTIONAL | M3: OPTIONAL | N3: REQUIRED | O3: AUTO
A4: Economy | B4: Law Name | C4: Law Number / Ref | D4: Last Amended | E4: Indicator ID | F4: Article / Section | G4: Discovery Tag | H4: Location Reference | I4: Verbatim Snippet | J4: Mapping Rationale | K4: Source URL | L4: Confidence | M4: Notes | N4: Language of Source | O4: Pillar (auto — do not edit)
A5: Economy name (use official UN name: https://www.unescap.org/about/member-states) | B5: Full official statute name and year | C5: Official law/act number — e.g. 'Act 709', 'Law No. 27/2022', 'B.E. 2562', 'No. 26 of 2000' | D5: Year of most recent amendment. Leave blank if not amended. | E5: RDTII indicator code — e.g. "P6-I1" , "P6_I2" | F5: Exact article and paragraph — e.g. Art. 26(2) or S 13(1)(a) | G5: Enter "NEW" if not in sample kit; "KNOWN" if provided as example | H5: PDF: page number | HTML: URL anchor or section path (e.g. #s26, Part IV > s.26) | I5: Copy the EXACT text — no edits, no paraphrasing | J5: OPTIONAL. Max 300 chars. Format: "This [article] [prohibits/requires/permits/establishes] [what]. Maps to [indicator] because [reason]." | K5: Direct URL to the law on the official government portal | L5: Optional. Model certainty score for this mapping (0.00 – 1.00) | M5: Optional: flag unusual cases, bilingual sources, OCR issues | N5: Original language of the legal document — e.g. Thai, Vietnamese, Bahasa Indonesia, Russian, English. Drives criterion C1c. | O5: Derived from your Indicator ID. Feeds the Coverage Matrix. Leave the formula alone.
A6: ▸ EXAMPLE ROWS (not real submissions — delete rows 7 and 8 before submitting)
A7: Singapore | B7: Personal Data Protection Act 2012 | C7: Act 26 of 2012 | D7: 2025 | E7: 6.4 | F7: s. 26(1) | G7: KNOWN | H7: page 32 | I7: An organisation shall not transfer any personal data to a country or territory outside Singapore except in accordance with requirements prescribed under this Act… | J7: This s. 26(1) permits cross-border transfer subject to prescribed requirements. It is a conditional flow regime (6.4), not an outright ban (6.1). | K7: https://sso.agc.gov.sg/Act/PDPA2012 | L7: 0.95 | M7: Trap: 'must not transfer UNLESS' is 6.4, never 6.1. | N7: English
A8: Singapore | B8: Personal Data Protection Act 2012 | C8: Act 26 of 2012 | D8: 2025 | E8: 7.4 | F8: s. 11(3) | G8: KNOWN | H8: page 18 | I8: An organisation shall designate at least one individual to be responsible for ensuring that the organisation complies with this Act. | J8: This s. 11(3) requires designation of a data protection officer, which is the DPO limb of indicator 7.4. | K8: https://sso.agc.gov.sg/Act/PDPA2012 | L8: 0.90 | N8: English
O9: =IF($E9="","",IFERROR(INT($E9),IFERROR(VALUE(LEFT($E9,FIND(".",$E9)-1)),"?")))
O10: =IF($E10="","",IFERROR(INT($E10),IFERROR(VALUE(LEFT($E10,FIND(".",$E10)-1)),"?")))
O11: =IF($E11="","",IFERROR(INT($E11),IFERROR(VALUE(LEFT($E11,FIND(".",$E11)-1)),"?")))
O12: =IF($E12="","",IFERROR(INT($E12),IFERROR(VALUE(LEFT($E12,FIND(".",$E12)-1)),"?")))
O13: =IF($E13="","",IFERROR(INT($E13),IFERROR(VALUE(LEFT($E13,FIND(".",$E13)-1)),"?")))
O14: =IF($E14="","",IFERROR(INT($E14),IFERROR(VALUE(LEFT($E14,FIND(".",$E14)-1)),"?")))
O15: =IF($E15="","",IFERROR(INT($E15),IFERROR(VALUE(LEFT($E15,FIND(".",$E15)-1)),"?")))
O16: =IF($E16="","",IFERROR(INT($E16),IFERROR(VALUE(LEFT($E16,FIND(".",$E16)-1)),"?")))
O17: =IF($E17="","",IFERROR(INT($E17),IFERROR(VALUE(LEFT($E17,FIND(".",$E17)-1)),"?")))
O18: =IF($E18="","",IFERROR(INT($E18),IFERROR(VALUE(LEFT($E18,FIND(".",$E18)-1)),"?")))
O19: =IF($E19="","",IFERROR(INT($E19),IFERROR(VALUE(LEFT($E19,FIND(".",$E19)-1)),"?")))
O20: =IF($E20="","",IFERROR(INT($E20),IFERROR(VALUE(LEFT($E20,FIND(".",$E20)-1)),"?")))
... O109: =IF($E109="","",IFERROR(INT($E109),IFERROR(VALUE(LEFT($E109,FIND(".",$E109)-1)),"?")))

Sheet Indicator Reference
A1: RDTII 2.1 — Indicator Reference (all 12 pillars)
A2: Source: ESCAP-RDTII-2.1 Round 1 Database, 'RDTII 2.1 Methodology' sheet. Use these codes exactly, as text. Gaps in the numbering are intentional. Pillars 6 and 7 are mandatory for this hackathon; the sealed live task on 15 October may fall in any pillar.
A3: Pillar | B3: Indicator ID | C3: Indicator (policy issue) | D3: Weight in pillar | E3: Exceptions / notes
A4: Pillar 1: Tariffs and Trade Defence
B5: 1.4 | C5: Trade defence measures including anti-dumping, countervailing duties and safeguards on ICT-related goods imported by other economies within the considered United Nations region
A6: Pillar 2: Public Procurement
B7: 2.1 | C7: Foreign exclusions from public procurement related to ICT goods and digital services
B8: 2.2 | C8: Specific requirements on source codes, encryption and trade secrets
B9: 2.3 | C9: Limitations in procurement bidding
A10: Pillar 3: Foreign Direct Investment
B11: 3.1 | C11: Foreign equity limits in sectors relevant to digital trade | E11: Exception: Not cover foreign equity cap in telecom sector (covered under Pillar 5) and e-commerce sector (covered under Pillar 12)
B12: 3.2 | C12: Joint venture requirements
B13: 3.3 | C13: Nationality or residency requirements for board of directors or managers
B14: 3.4 | C14: Screening of investment and acquisitions | E14: Exception: Anti-trust measures related to M&A are not considered a restriction, unless discriminatory.
B15: 3.5 | C15: Commercial presence requirements to offer cross-border services in sectors relevant to digital trade
A16: Pillar 4: Intellectual Property Rights
B17: 4.01 | C17: Patent application issues
B18: 4.2 | C18: Patent enforcement issues: civil and administrative procedures and remedies; and provisional measures
B19: 4.3 | C19: Patent enforcement issues: others
B20: 4.5 | C20: Lack of copyright framework and exceptions
B21: 4.6 | C21: Online copyright enforcement issues: civil and administrative procedures and remedies; and provisional measures
B22: 4.9 | C22: Mandatory disclosure of trade secrets, such as souce code and algorithms
B23: 4.1 | C23: Lack of effective trade secrets legal framework
A24: Pillar 5: Telecom Regulations & Competition
B25: 5.1 | C25: Lack of passive infrastructure sharing
B26: 5.2 | C26: Foreign equity limits in telecom sector
B27: 5.3 | C27: Shares owned by the Government in telecom companies
B28: 5.4 | C28: Lack of functional/accounting separation
B29: 5.5 | C29: Licensing requirements in telecom sector for operators
B30: 5.7 | C30: Lack of independent telecom authority
A31: Pillar 6: Cross-border Data Policies
B32: 6.1 | C32: Ban and local processing requirements | D32: 38% | E32: Exception: Not score data localization measure applied to government data.
B33: 6.2 | C33: Local storage requirements | D33: 12% | E33: Exception: Not score data localization measure applied to government data.
B34: 6.3 | C34: Infrastructure requirements | D34: 31% | E34: Exception: Not score data localization measure applied to government data.
B35: 6.4 | C35: Conditional flow regimes | D35: 12% | E35: Exception: Not score data localization measure applied to government data.
B36: 6.5 | C36: Not in an agreement with binding commitments on data transfer | D36: 8% | E36: From the RDTII 2.1 framework document; not present in the Round 1 database extract.
A37: Pillar 7: Domestic Data Protection & Privacy
B38: 7.1 | C38: Lack of comprehensive legal framework for data protection | D38: 31%
B39: 7.2 | C39: Lack of dedicated legal framework for cybersecurity | D39: 31%
B40: 7.3 | C40: Minimum period of data retention requirements | D40: 16% | E40: Exception: Not score requirement applied to government data.
...

Sheet Coverage Matrix
A1: Coverage Matrix — provisions per economy × pillar
A2: Auto-calculated from the Output Data sheet via the Pillar (auto) column. Do not edit the formulas. Pillars 6 and 7 are mandatory.
A3: Economy | B3: 1 Tariffs and Trade Defence | C3: 2 Public Procurement | D3: 3 Foreign Direct Investment | E3: 4 Intellectual Property Rights | F3: 5 Telecom Regulations & Competition | G3: 6 Cross-border Data Policies | H3: 7 Domestic Data Protection & Privacy | I3: 8 Internet Intermediary Liability | J3: 9 Content Access | K3: 10 Non-technical NTMs | L3: 11 Standards and Procedures | M3: 12 Online Sales and Transactions | N3: Row total
A4: Australia | B4: =COUNTIFS('Output Data'!$O$9:$O$109,1,'Output Data'!$A$9:$A$109,$A4) -> 0 | C4: =COUNTIFS('Output Data'!$O$9:$O$109,2,'Output Data'!$A$9:$A$109,$A4) -> 0 | D4: =COUNTIFS('Output Data'!$O$9:$O$109,3,'Output Data'!$A$9:$A$109,$A4) -> 0 | E4: =COUNTIFS('Output Data'!$O$9:$O$109,4,'Output Data'!$A$9:$A$109,$A4) -> 0 | F4: =COUNTIFS('Output Data'!$O$9:$O$109,5,'Output Data'!$A$9:$A$109,$A4) -> 0 | G4: =COUNTIFS('Output Data'!$O$9:$O$109,6,'Output Data'!$A$9:$A$109,$A4) -> 0 | H4: =COUNTIFS('Output Data'!$O$9:$O$109,7,'Output Data'!$A$9:$A$109,$A4) -> 0 | I4: =COUNTIFS('Output Data'!$O$9:$O$109,8,'Output Data'!$A$9:$A$109,$A4) -> 0 | J4: =COUNTIFS('Output Data'!$O$9:$O$109,9,'Output Data'!$A$9:$A$109,$A4) -> 0 | K4: =COUNTIFS('Output Data'!$O$9:$O$109,10,'Output Data'!$A$9:$A$109,$A4) -> 0 | L4: =COUNTIFS('Output Data'!$O$9:$O$109,11,'Output Data'!$A$9:$A$109,$A4) -> 0 | M4: =COUNTIFS('Output Data'!$O$9:$O$109,12,'Output Data'!$A$9:$A$109,$A4) -> 0 | N4: =SUM(B4:M4) -> 0
A5: Bangladesh | B5: =COUNTIFS('Output Data'!$O$9:$O$109,1,'Output Data'!$A$9:$A$109,$A5) -> 0 | C5: =COUNTIFS('Output Data'!$O$9:$O$109,2,'Output Data'!$A$9:$A$109,$A5) -> 0 | D5: =COUNTIFS('Output Data'!$O$9:$O$109,3,'Output Data'!$A$9:$A$109,$A5) -> 0 | E5: =COUNTIFS('Output Data'!$O$9:$O$109,4,'Output Data'!$A$9:$A$109,$A5) -> 0 | F5: =COUNTIFS('Output Data'!$O$9:$O$109,5,'Output Data'!$A$9:$A$109,$A5) -> 0 | G5: =COUNTIFS('Output Data'!$O$9:$O$109,6,'Output Data'!$A$9:$A$109,$A5) -> 0 | H5: =COUNTIFS('Output Data'!$O$9:$O$109,7,'Output Data'!$A$9:$A$109,$A5) -> 0 | I5: =COUNTIFS('Output Data'!$O$9:$O$109,8,'Output Data'!$A$9:$A$109,$A5) -> 0 | J5: =COUNTIFS('Output Data'!$O$9:$O$109,9,'Output Data'!$A$9:$A$109,$A5) -> 0 | K5: =COUNTIFS('Output Data'!$O$9:$O$109,10,'Output Data'!$A$9:$A$109,$A5) -> 0 | L5: =COUNTIFS('Output Data'!$O$9:$O$109,11,'Output Data'!$A$9:$A$109,$A5) -> 0 | M5: =COUNTIFS('Output Data'!$O$9:$O$109,12,'Output Data'!$A$9:$A$109,$A5) -> 0 | N5: =SUM(B5:M5) -> 0
A6: Bhutan | B6: =COUNTIFS('Output Data'!$O$9:$O$109,1,'Output Data'!$A$9:$A$109,$A6) -> 0 | C6: =COUNTIFS('Output Data'!$O$9:$O$109,2,'Output Data'!$A$9:$A$109,$A6) -> 0 | D6: =COUNTIFS('Output Data'!$O$9:$O$109,3,'Output Data'!$A$9:$A$109,$A6) -> 0 | E6: =COUNTIFS('Output Data'!$O$9:$O$109,4,'Output Data'!$A$9:$A$109,$A6) -> 0 | F6: =COUNTIFS('Output Data'!$O$9:$O$109,5,'Output Data'!$A$9:$A$109,$A6) -> 0 | G6: =COUNTIFS('Output Data'!$O$9:$O$109,6,'Output Data'!$A$9:$A$109,$A6) -> 0 | H6: =COUNTIFS('Output Data'!$O$9:$O$109,7,'Output Data'!$A$9:$A$109,$A6) -> 0 | I6: =COUNTIFS('Output Data'!$O$9:$O$109,8,'Output Data'!$A$9:$A$109,$A6) -> 0 | J6: =COUNTIFS('Output Data'!$O$9:$O$109,9,'Output Data'!$A$9:$A$109,$A6) -> 0 | K6: =COUNTIFS('Output Data'!$O$9:$O$109,10,'Output Data'!$A$9:$A$109,$A6) -> 0 | L6: =COUNTIFS('Output Data'!$O$9:$O$109,11,'Output Data'!$A$9:$A$109,$A6) -> 0 | M6: =COUNTIFS('Output Data'!$O$9:$O$109,12,'Output Data'!$A$9:$A$109,$A6) -> 0 | N6: =SUM(B6:M6) -> 0
A7: Brunei Darussalam | B7: =COUNTIFS('Output Data'!$O$9:$O$109,1,'Output Data'!$A$9:$A$109,$A7) -> 0 | C7: =COUNTIFS('Output Data'!$O$9:$O$109,2,'Output Data'!$A$9:$A$109,$A7) -> 0 | D7: =COUNTIFS('Output Data'!$O$9:$O$109,3,'Output Data'!$A$9:$A$109,$A7) -> 0 | E7: =COUNTIFS('Output Data'!$O$9:$O$109,4,'Output Data'!$A$9:$A$109,$A7) -> 0 | F7: =COUNTIFS('Output Data'!$O$9:$O$109,5,'Output Data'!$A$9:$A$109,$A7) -> 0 | G7: =COUNTIFS('Output Data'!$O$9:$O$109,6,'Output Data'!$A$9:$A$109,$A7) -> 0 | H7: =COUNTIFS('Output Data'!$O$9:$O$109,7,'Output Data'!$A$9:$A$109,$A7) -> 0 | I7: =COUNTIFS('Output Data'!$O$9:$O$109,8,'Output Data'!$A$9:$A$109,$A7) -> 0 | J7: =COUNTIFS('Output Data'!$O$9:$O$109,9,'Output Data'!$A$9:$A$109,$A7) -> 0 | K7: =COUNTIFS('Output Data'!$O$9:$O$109,10,'Output Data'!$A$9:$A$109,$A7) -> 0 | L7: =COUNTIFS('Output Data'!$O$9:$O$109,11,'Output Data'!$A$9:$A$109,$A7) -> 0 | M7: =COUNTIFS('Output Data'!$O$9:$O$109,12,'Output Data'!$A$9:$A$109,$A7) -> 0 | N7: =SUM(B7:M7) -> 0
A8: Cambodia | B8: =COUNTIFS('Output Data'!$O$9:$O$109,1,'Output Data'!$A$9:$A$109,$A8) -> 0 | C8: =COUNTIFS('Output Data'!$O$9:$O$109,2,'Output Data'!$A$9:$A$109,$A8) -> 0 | D8: =COUNTIFS('Output Data'!$O$9:$O$109,3,'Output Data'!$A$9:$A$109,$A8) -> 0 | E8: =COUNTIFS('Output Data'!$O$9:$O$109,4,'Output Data'!$A$9:$A$109,$A8) -> 0 | F8: =COUNTIFS('Output Data'!$O$9:$O$109,5,'Output Data'!$A$9:$A$109,$A8) -> 0 | G8: =COUNTIFS('Output Data'!$O$9:$O$109,6,'Output Data'!$A$9:$A$109,$A8) -> 0 | H8: =COUNTIFS('Output Data'!$O$9:$O$109,7,'Output Data'!$A$9:$A$109,$A8) -> 0 | I8: =COUNTIFS('Output Data'!$O$9:$O$109,8,'Output Data'!$A$9:$A$109,$A8) -> 0 | J8: =COUNTIFS('Output Data'!$O$9:$O$109,9,'Output Data'!$A$9:$A$109,$A8) -> 0 | K8: =COUNTIFS('Output Data'!$O$9:$O$109,10,'Output Data'!$A$9:$A$109,$A8) -> 0 | L8: =COUNTIFS('Output Data'!$O$9:$O$109,11,'Output Data'!$A$9:$A$109,$A8) -> 0 | M8: =COUNTIFS('Output Data'!$O$9:$O$109,12,'Output Data'!$A$9:$A$109,$A8) -> 0 | N8: =SUM(B8:M8) -> 0
A9: China | B9: =COUNTIFS('Output Data'!$O$9:$O$109,1,'Output Data'!$A$9:$A$109,$A9) -> 0 | C9: =COUNTIFS('Output Data'!$O$9:$O$109,2,'Output Data'!$A$9:$A$109,$A9) -> 0 | D9: =COUNTIFS('Output Data'!$O$9:$O$109,3,'Output Data'!$A$9:$A$109,$A9) -> 0 | E9: =COUNTIFS('Output Data'!$O$9:$O$109,4,'Output Data'!$A$9:$A$109,$A9) -> 0 | F9: =COUNTIFS('Output Data'!$O$9:$O$109,5,'Output Data'!$A$9:$A$109,$A9) -> 0 | G9: =COUNTIFS('Output Data'!$O$9:$O$109,6,'Output Data'!$A$9:$A$109,$A9) -> 0 | H9: =COUNTIFS('Output Data'!$O$9:$O$109,7,'Output Data'!$A$9:$A$109,$A9) -> 0 | I9: =COUNTIFS('Output Data'!$O$9:$O$109,8,'Output Data'!$A$9:$A$109,$A9) -> 0 | J9: =COUNTIFS('Output Data'!$O$9:$O$109,9,'Output Data'!$A$9:$A$109,$A9) -> 0 | K9: =COUNTIFS('Output Data'!$O$9:$O$109,10,'Output Data'!$A$9:$A$109,$A9) -> 0 | L9: =COUNTIFS('Output Data'!$O$9:$O$109,11,'Output Data'!$A$9:$A$109,$A9) -> 0 | M9: =COUNTIFS('Output Data'!$O$9:$O$109,12,'Output Data'!$A$9:$A$109,$A9) -> 0 | N9: =SUM(B9:M9) -> 0
A10: Fiji | B10: =COUNTIFS('Output Data'!$O$9:$O$109,1,'Output Data'!$A$9:$A$109,$A10) -> 0 | C10: =COUNTIFS('Output Data'!$O$9:$O$109,2,'Output Data'!$A$9:$A$109,$A10) -> 0 | D10: =COUNTIFS('Output Data'!$O$9:$O$109,3,'Output Data'!$A$9:$A$109,$A10) -> 0 | E10: =COUNTIFS('Output Data'!$O$9:$O$109,4,'Output Data'!$A$9:$A$109,$A10) -> 0 | F10: =COUNTIFS('Output Data'!$O$9:$O$109,5,'Output Data'!$A$9:$A$109,$A10) -> 0 | G10: =COUNTIFS('Output Data'!$O$9:$O$109,6,'Output Data'!$A$9:$A$109,$A10) -> 0 | H10: =COUNTIFS('Output Data'!$O$9:$O$109,7,'Output Data'!$A$9:$A$109,$A10) -> 0 | I10: =COUNTIFS('Output Data'!$O$9:$O$109,8,'Output Data'!$A$9:$A$109,$A10) -> 0 | J10: =COUNTIFS('Output Data'!$O$9:$O$109,9,'Output Data'!$A$9:$A$109,$A10) -> 0 | K10: =COUNTIFS('Output Data'!$O$9:$O$109,10,'Output Data'!$A$9:$A$109,$A10) -> 0 | L10: =COUNTIFS('Output Data'!$O$9:$O$109,11,'Output Data'!$A$9:$A$109,$A10) -> 0 | M10: =COUNTIFS('Output Data'!$O$9:$O$109,12,'Output Data'!$A$9:$A$109,$A10) -> 0 | N10: =SUM(B10:M10) -> 0
A11: India | B11: =COUNTIFS('Output Data'!$O$9:$O$109,1,'Output Data'!$A$9:$A$109,$A11) -> 0 | C11: =COUNTIFS('Output Data'!$O$9:$O$109,2,'Output Data'!$A$9:$A$109,$A11) -> 0 | D11: =COUNTIFS('Output Data'!$O$9:$O$109,3,'Output Data'!$A$9:$A$109,$A11) -> 0 | E11: =COUNTIFS('Output Data'!$O$9:$O$109,4,'Output Data'!$A$9:$A$109,$A11) -> 0 | F11: =COUNTIFS('Output Data'!$O$9:$O$109,5,'Output Data'!$A$9:$A$109,$A11) -> 0 | G11: =COUNTIFS('Output Data'!$O$9:$O$109,6,'Output Data'!$A$9:$A$109,$A11) -> 0 | H11: =COUNTIFS('Output Data'!$O$9:$O$109,7,'Output Data'!$A$9:$A$109,$A11) -> 0 | I11: =COUNTIFS('Output Data'!$O$9:$O$109,8,'Output Data'!$A$9:$A$109,$A11) -> 0 | J11: =COUNTIFS('Output Data'!$O$9:$O$109,9,'Output Data'!$A$9:$A$109,$A11) -> 0 | K11: =COUNTIFS('Output Data'!$O$9:$O$109,10,'Output Data'!$A$9:$A$109,$A11) -> 0 | L11: =COUNTIFS('Output Data'!$O$9:$O$109,11,'Output Data'!$A$9:$A$109,$A11) -> 0 | M11: =COUNTIFS('Output Data'!$O$9:$O$109,12,'Output Data'!$A$9:$A$109,$A11) -> 0 | N11: =SUM(B11:M11) -> 0
A12: Indonesia | B12: =COUNTIFS('Output Data'!$O$9:$O$109,1,'Output Data'!$A$9:$A$109,$A12) -> 0 | C12: =COUNTIFS('Output Data'!$O$9:$O$109,2,'Output Data'!$A$9:$A$109,$A12) -> 0 | D12: =COUNTIFS('Output Data'!$O$9:$O$109,3,'Output Data'!$A$9:$A$109,$A12) -> 0 | E12: =COUNTIFS('Output Data'!$O$9:$O$109,4,'Output Data'!$A$9:$A$109,$A12) -> 0 | F12: =COUNTIFS('Output Data'!$O$9:$O$109,5,'Output Data'!$A$9:$A$109,$A12) -> 0 | G12: =COUNTIFS('Output Data'!$O$9:$O$109,6,'Output Data'!$A$9:$A$109,$A12) -> 0 | H12: =COUNTIFS('Output Data'!$O$9:$O$109,7,'Output Data'!$A$9:$A$109,$A12) -> 0 | I12: =COUNTIFS('Output Data'!$O$9:$O$109,8,'Output Data'!$A$9:$A$109,$A12) -> 0 | J12: =COUNTIFS('Output Data'!$O$9:$O$109,9,'Output Data'!$A$9:$A$109,$A12) -> 0 | K12: =COUNTIFS('Output Data'!$O$9:$O$109,10,'Output Data'!$A$9:$A$109,$A12) -> 0 | L12: =COUNTIFS('Output Data'!$O$9:$O$109,11,'Output Data'!$A$9:$A$109,$A12) -> 0 | M12: =COUNTIFS('Output Data'!$O$9:$O$109,12,'Output Data'!$A$9:$A$109,$A12) -> 0 | N12: =SUM(B12:M12) -> 0
A13: Japan | B13: =COUNTIFS('Output Data'!$O$9:$O$109,1,'Output Data'!$A$9:$A$109,$A13) -> 0 | C13: =COUNTIFS('Output Data'!$O$9:$O$109,2,'Output Data'!$A$9:$A$109,$A13) -> 0 | D13: =COUNTIFS('Output Data'!$O$9:$O$109,3,'Output Data'!$A$9:$A$109,$A13) -> 0 | E13: =COUNTIFS('Output Data'!$O$9:$O$109,4,'Output Data'!$A$9:$A$109,$A13) -> 0 | F13: =COUNTIFS('Output Data'!$O$9:$O$109,5,'Output Data'!$A$9:$A$109,$A13) -> 0 | G13: =COUNTIFS('Output Data'!$O$9:$O$109,6,'Output Data'!$A$9:$A$109,$A13) -> 0 | H13: =COUNTIFS('Output Data'!$O$9:$O$109,7,'Output Data'!$A$9:$A$109,$A13) -> 0 | I13: =COUNTIFS('Output Data'!$O$9:$O$109,8,'Output Data'!$A$9:$A$109,$A13) -> 0 | J13: =COUNTIFS('Output Data'!$O$9:$O$109,9,'Output Data'!$A$9:$A$109,$A13) -> 0 | K13: =COUNTIFS('Output Data'!$O$9:$O$109,10,'Output Data'!$A$9:$A$109,$A13) -> 0 | L13: =COUNTIFS('Output Data'!$O$9:$O$109,11,'Output Data'!$A$9:$A$109,$A13) -> 0 | M13: =COUNTIFS('Output Data'!$O$9:$O$109,12,'Output Data'!$A$9:$A$109,$A13) -> 0 | N13: =SUM(B13:M13) -> 0
A14: Kazakhstan | B14: =COUNTIFS('Output Data'!$O$9:$O$109,1,'Output Data'!$A$9:$A$109,$A14) -> 0 | C14: =COUNTIFS('Output Data'!$O$9:$O$109,2,'Output Data'!$A$9:$A$109,$A14) -> 0 | D14: =COUNTIFS('Output Data'!$O$9:$O$109,3,'Output Data'!$A$9:$A$109,$A14) -> 0 | E14: =COUNTIFS('Output Data'!$O$9:$O$109,4,'Output Data'!$A$9:$A$109,$A14) -> 0 | F14: =COUNTIFS('Output Data'!$O$9:$O$109,5,'Output Data'!$A$9:$A$109,$A14) -> 0 | G14: =COUNTIFS('Output Data'!$O$9:$O$109,6,'Output Data'!$A$9:$A$109,$A14) -> 0 | H14: =COUNTIFS('Output Data'!$O$9:$O$109,7,'Output Data'!$A$9:$A$109,$A14) -> 0 | I14: =COUNTIFS('Output Data'!$O$9:$O$109,8,'Output Data'!$A$9:$A$109,$A14) -> 0 | J14: =COUNTIFS('Output Data'!$O$9:$O$109,9,'Output Data'!$A$9:$A$109,$A14) -> 0 | K14: =COUNTIFS('Output Data'!$O$9:$O$109,10,'Output Data'!$A$9:$A$109,$A14) -> 0 | L14: =COUNTIFS('Output Data'!$O$9:$O$109,11,'Output Data'!$A$9:$A$109,$A14) -> 0 | M14: =COUNTIFS('Output Data'!$O$9:$O$109,12,'Output Data'!$A$9:$A$109,$A14) -> 0 | N14: =SUM(B14:M14) -> 0
A15: Kyrgyzstan | B15: =COUNTIFS('Output Data'!$O$9:$O$109,1,'Output Data'!$A$9:$A$109,$A15) -> 0 | C15: =COUNTIFS('Output Data'!$O$9:$O$109,2,'Output Data'!$A$9:$A$109,$A15) -> 0 | D15: =COUNTIFS('Output Data'!$O$9:$O$109,3,'Output Data'!$A$9:$A$109,$A15) -> 0 | E15: =COUNTIFS('Output Data'!$O$9:$O$109,4,'Output Data'!$A$9:$A$109,$A15) -> 0 | F15: =COUNTIFS('Output Data'!$O$9:$O$109,5,'Output Data'!$A$9:$A$109,$A15) -> 0 | G15: =COUNTIFS('Output Data'!$O$9:$O$109,6,'Output Data'!$A$9:$A$109,$A15) -> 0 | H15: =COUNTIFS('Output Data'!$O$9:$O$109,7,'Output Data'!$A$9:$A$109,$A15) -> 0 | I15: =COUNTIFS('Output Data'!$O$9:$O$109,8,'Output Data'!$A$9:$A$109,$A15) -> 0 | J15: =COUNTIFS('Output Data'!$O$9:$O$109,9,'Output Data'!$A$9:$A$109,$A15) -> 0 | K15: =COUNTIFS('Output Data'!$O$9:$O$109,10,'Output Data'!$A$9:$A$109,$A15) -> 0 | L15: =COUNTIFS('Output Data'!$O$9:$O$109,11,'Output Data'!$A$9:$A$109,$A15) -> 0 | M15: =COUNTIFS('Output Data'!$O$9:$O$109,12,'Output Data'!$A$9:$A$109,$A15) -> 0 | N15: =SUM(B15:M15) -> 0
... A37: Viet Nam | B37: =COUNTIFS('Output Data'!$O$9:$O$109,1,'Output Data'!$A$9:$A$109,$A37) -> 0 | C37: =COUNTIFS('Output Data'!$O$9:$O$109,2,'Output Data'!$A$9:$A$109,$A37) -> 0 | D37: =COUNTIFS('Output Data'!$O$9:$O$109,3,'Output Data'!$A$9:$A$109,$A37) -> 0 | E37: =COUNTIFS('Output Data'!$O$9:$O$109,4,'Output Data'!$A$9:$A$109,$A37) -> 0 | F37: =COUNTIFS('Output Data'!$O$9:$O$109,5,'Output Data'!$A$9:$A$109,$A37) -> 0 | G37: =COUNTIFS('Output Data'!$O$9:$O$109,6,'Output Data'!$A$9:$A$109,$A37) -> 0 | H37: =COUNTIFS('Output Data'!$O$9:$O$109,7,'Output Data'!$A$9:$A$109,$A37) -> 0 | I37: =COUNTIFS('Output Data'!$O$9:$O$109,8,'Output Data'!$A$9:$A$109,$A37) -> 0 | J37: =COUNTIFS('Output Data'!$O$9:$O$109,9,'Output Data'!$A$9:$A$109,$A37) -> 0 | K37: =COUNTIFS('Output Data'!$O$9:$O$109,10,'Output Data'!$A$9:$A$109,$A37) -> 0 | L37: =COUNTIFS('Output Data'!$O$9:$O$109,11,'Output Data'!$A$9:$A$109,$A37) -> 0 | M37: =COUNTIFS('Output Data'!$O$9:$O$109,12,'Output Data'!$A$9:$A$109,$A37) -> 0 | N37: =SUM(B37:M37) -> 0
A38: Column total | B38: =SUM(B4:B37) -> 0 | C38: =SUM(C4:C37) -> 0 | D38: =SUM(D4:D37) -> 0 | E38: =SUM(E4:E37) -> 0 | F38: =SUM(F4:F37) -> 0 | G38: =SUM(G4:G37) -> 0 | H38: =SUM(H4:H37) -> 0 | I38: =SUM(I4:I37) -> 0 | ... N38: =SUM(N4:N37) -> 0
A40: Economies with at least one provision: | D40: =SUMPRODUCT(--(N4:N37>0)) -> 0
A41: C1a asks for three or more diverse economies, processed autonomously.

Sheet Engine Comparison
A1: Finale morning — engine comparison (criterion C5b, 4 points)
A2: Completed during the live hour on 15 October and submitted with your evidence. Cover every provision either engine produced. The second engine re-reads documents already downloaded and fetches nothing new.
A3: 1 · Per-engine summary
A4: Field | B4: Engine A — first pass | C4: Engine B — second pass
A5: Provider and model name
A6: Start time (hh:mm)
A7: End time (hh:mm)
A8: Elapsed (minutes)
A9: Documents fetched during this pass
A10: Cost of this pass (US$)
A12: Engine B's 'documents fetched' must be 0. A steward checks this against the Run Record.
A14: 2 · Provision-by-provision comparison
A15: # | B15: Law Name | C15: Article / Section | D15: Indicator ID | E15: Found by | F15: Indicator differs? | G15: Citation differs? | H15: Quoted words differ? | I15: How they differ — one line
A16: 1 | B16: Electronic Transactions Act B.E. 2544 | C16: s. 26 | D16: 12.3 | E16: Both | F16: No | G16: Yes | H16: No | I16: Engine A cited s. 26(1), Engine B cited s. 26 — same text, A is the more precise citation
A58: Found by Engine A only: | D58: =COUNTIF(E17:E56,"Engine A only") -> 0
A59: Found by Engine B only: | D59: =COUNTIF(E17:E56,"Engine B only") -> 0
A60: Found by both: | D60: =COUNTIF(E17:E56,"Both") -> 0
A62: 3 · Which output would you hand to a ministry, and why?
A68: One paragraph, in your own words. Two engines agreeing is a good result — say so, and say what it tells you. This is the part that carries the marks, because it is the part a menu cannot fake.

Sheet Run Record
A1: Finale morning — run record
A2: Evidence that the hour happened as described. The document list is the hard check: if no documents were fetched during the hour, C5a scores zero regardless of what the evidence file contains.
A3: 1 · Engine runs
A4: Engine | B4: Provider / model name | C4: Start (hh:mm) | D4: End (hh:mm) | E4: Elapsed (min) | F4: Cost (US$)
A5: Engine A — first pass
A6: Engine B — second pass
A7: Total cost for the hour (US$) | F7: =SUM(F5:F6) -> 0
A9: 2 · Every document downloaded during the hour
A10: # | B10: Source URL | C10: Fetched during | D10: Time (hh:mm) | E10: Size (KB) | F10: File type
A11: 1 | B11: https://www.etda.or.th/…/ETA-2544.pdf | C11: Engine A pass | D11: 10:22 | E11: 812 | F11: PDF
A58: Documents fetched during the hour (Engine A): | E58: =COUNTIF(C12:C56,"Engine A pass") -> 0
A59: Documents fetched by Engine B — must be zero: | E59: =COUNTIF(C12:C56,"Engine B pass") -> 0
A61: 3 · Short note
A62: What worked
A63: What broke
A64: What a human should check first
A65: Headline cost for the hour (US$)
A66: Machine used (make, RAM, GPU if any)
A67: The two engines used

Sheet Submission Checklist
A1: Checklist before 30 September
A2: Tick every item. The live-test items cannot be fixed on 15 October — code is frozen at submission.
A3: # | B3: Item | C3: Status | D3: Notes / evidence
A4: 1 | B4: [Repository] GitHub repository is public and accessible to the secretariat
A5: 2 | B5: [Repository] Final release tag recorded — that exact tag is what will run on 15 October
A6: 3 | B6: [Repository] LICENSE file contains the Apache License 2.0 text
A7: 4 | B7: [Repository] README complete, following README_template_FINAL_ROUND.md — every section, not just Quick Start
A8: 5 | B8: [Repository] README Quick Start reaches a working system on a clean machine in under 30 minutes
A9: 6 | B9: [Deployment] Deployment guide included in the Stage 3 Word template, Section 1
A10: 7 | B10: [Deployment] Someone who did not build the tool deployed it from the guide alone, on a clean machine, in under 30 minutes
A11: 8 | B11: [Deployment] Docker / Python environment requirements documented; no hardcoded paths
A12: 9 | B12: [Architecture] The AI model backend is swappable from inside the interface, with no code or config change
A13: 10 | B13: [Architecture] Zone 1 (source discovery) and Zone 2 (extraction) are separate, documented modules
A14: 11 | B14: [Architecture] The human-review audit interface works and can be driven by a non-technical policy officer
A15: 12 | B15: [Compliance] The core pipeline runs end to end on the open-weights engine alone, with no proprietary API
... A32: 29 | B32: [Live test] After submission the interface can be left available for the marking period

Sheet Instructions
A1: How to complete the Final Round output template
A2: WHAT CHANGED SINCE ROUND 1
A3: Same columns | B3: The thirteen Round 1 columns are unchanged, in the same order. Your exporter should still work.
A4: One new column | B4: Language of Source (column N) — the original language of the legal document. It drives criterion C1c.
A5: One automatic column | B5: Pillar (column O) is a formula that reads your Indicator ID. Do not type in it and do not delete it; the Coverage Matrix reads from it.
A6: Scope is wider | B6: Round 1 was pillars 6 and 7 only. The final round accepts any RDTII pillar; 6 and 7 remain mandatory. The Indicator Reference sheet now lists all twelve.
A7: Two morning sheets | B7: Engine Comparison and Run Record are completed during the live hour on 15 October, not before.
A8: Your interface | B8: A submitted deliverable, not a file you upload: the system a reviewer reaches by deploying your repository at the declared tag. C3a and C3b (15 points) are marked on it during the fortnight.
A9: Interface walkthrough | B9: New: a 3-4 minute screen recording of your audit view, submitted with the Word document. It is the fallback if we cannot deploy your system from your guide.
A10: GENERAL RULES
A11: Delete example rows | B11: Remove rows 7 and 8 before submitting. They are illustration only.
A12: Do not rename columns | B12: Column names and order must match this template exactly. The secretariat validates against them.
A13: One row per provision | B13: Each article or paragraph that maps to an indicator is one row. A provision touching two indicators gets two rows.
A14: No merged cells in data | B14: Keep every cell independent in the data area.
A15: INDICATOR IDs — READ THIS
A16: Format | B16: Write the RDTII 2.1 code exactly: 6.1, 6.4, 7.3, 12.3, 12.9. Not 'P6-I1', not 'Pillar 6 Indicator 1'.
A17: Store as text | B17: Column E is formatted as text. This matters: entered as a number, 12.10 collapses to 12.1 and 4.01 to 4.1, and the two are different indicators.
A18: Where they come from | B18: The Indicator Reference sheet, taken from the RDTII 2.1 Methodology in the Round 1 database. Gaps in the numbering are intentional.
A19: FIELD RULES
A20: Economy | B20: Official UN country name, e.g. Lao People's Democratic Republic, Viet Nam.
A21: Law Name | B21: Full official name plus year. Do not abbreviate.
A22: Article / Section | B22: Article number AND paragraph, e.g. Art. 26(2), s. 16(1). Cite the section, not just the act — a real act cited to the wrong section scores zero.
A23: Location Reference | B23: PDF page number, or an HTML anchor or section path.
A24: Verbatim Snippet | B24: The exact text. No editing, summarising or paraphrasing. Verified against the source.
A25: Mapping Rationale | B25: Max 300 characters. Name the legal mechanism: 'This s. 26(1) permits transfer subject to prescribed requirements — a conditional flow regime.' Not 'this is about data'.
A26: Discovery Tag | B26: NEW = your tool found it and it is not in the 2025 baseline you hold. KNOWN = it was in the sample kit.
A27: Language of Source | B27: The original language of the document, not the language you translated into.
A28: Confidence | B28: Optional, 0.00–1.00. Flagging low confidence is treated as a strength, not a weakness.
A29: THE LIVE TEST IS SEALED
A30: What you know now | B30: The task uses one of the nine economies whose 2025 RDTII database you hold — Thailand, Viet Nam, Indonesia, China, India, Kazakhstan, Lao PDR, Mongolia, the Russian Federation — with one pillar and two indicators.
A31: What you learn on the day | B31: Which economy, which pillar, which two indicators. Announced at the start of the hour and not before. It may be a pillar you were never asked to work.
A32: Not a menu | B32: You do not submit a list of jurisdictions to be tested from. Be ready for any of the nine.
A33: HOW THE FINAL ROUND IS MARKED
A34: The submission, 90 points | B34: C1a to C4b, marked by the secretariat between 30 September and 14 October against your sources.
A35: The live test, 10 points | B35: C5a discovery (6) and C5b engine swap (4), marked on 15 October.
A36: The judges, 50 points | B36: A separate sheet: their private hands-on session and your pitch. They do not see the desk-review scores.
A37: The advisory board, 10 points | B37: One question — which tool would you most want to see put to work.
A38: C1a in particular | B38: Three or more diverse economies processed autonomously, with minimal reconfiguration between them. Depth across three beats a thin pass over ten.
A39: SUBMISSION CHECKLIST
A40: See the Submission Checklist sheet | B40: Twenty-six items. The Live test items cannot be fixed on 15 October, because your code is frozen at submission.
